[2024-12-07T15:24:09.738+0000] {local_task_job_runner.py:123} INFO - ::group::Pre task execution logs
[2024-12-07T15:24:09.753+0000] {taskinstance.py:2613} INFO - Dependencies all met for dep_context=non-requeueable deps ti=<TaskInstance: medal_count_dag.create_table manual__2024-12-07T15:24:04.673694+00:00 [queued]>
[2024-12-07T15:24:09.759+0000] {taskinstance.py:2613} INFO - Dependencies all met for dep_context=requeueable deps ti=<TaskInstance: medal_count_dag.create_table manual__2024-12-07T15:24:04.673694+00:00 [queued]>
[2024-12-07T15:24:09.760+0000] {taskinstance.py:2866} INFO - Starting attempt 1 of 2
[2024-12-07T15:24:09.902+0000] {taskinstance.py:2889} INFO - Executing <Task(MySqlOperator): create_table> on 2024-12-07 15:24:04.673694+00:00
[2024-12-07T15:24:09.911+0000] {warnings.py:112} WARNING - /home/***/.local/lib/python3.12/site-packages/***/task/task_runner/standard_task_runner.py:70: DeprecationWarning: This process (pid=1457) is multi-threaded, use of fork() may lead to deadlocks in the child.
  pid = os.fork()

[2024-12-07T15:24:09.913+0000] {standard_task_runner.py:72} INFO - Started process 1459 to run task
[2024-12-07T15:24:09.913+0000] {standard_task_runner.py:104} INFO - Running: ['***', 'tasks', 'run', 'medal_count_dag', 'create_table', 'manual__2024-12-07T15:24:04.673694+00:00', '--job-id', '3', '--raw', '--subdir', 'DAGS_FOLDER/main.py', '--cfg-path', '/tmp/tmp1lxrb1pq']
[2024-12-07T15:24:09.915+0000] {standard_task_runner.py:105} INFO - Job 3: Subtask create_table
[2024-12-07T15:24:09.957+0000] {task_command.py:467} INFO - Running <TaskInstance: medal_count_dag.create_table manual__2024-12-07T15:24:04.673694+00:00 [running]> on host a693d8a2436c
[2024-12-07T15:24:10.018+0000] {taskinstance.py:3132} INFO - Exporting env vars: AIRFLOW_CTX_DAG_OWNER='***' AIRFLOW_CTX_DAG_ID='medal_count_dag' AIRFLOW_CTX_TASK_ID='create_table' AIRFLOW_CTX_EXECUTION_DATE='2024-12-07T15:24:04.673694+00:00' AIRFLOW_CTX_TRY_NUMBER='1' AIRFLOW_CTX_DAG_RUN_ID='manual__2024-12-07T15:24:04.673694+00:00'
[2024-12-07T15:24:10.020+0000] {logging_mixin.py:190} INFO - Task instance is in running state
[2024-12-07T15:24:10.020+0000] {logging_mixin.py:190} INFO -  Previous state of the Task instance: queued
[2024-12-07T15:24:10.021+0000] {logging_mixin.py:190} INFO - Current task name:create_table state:running start_date:2024-12-07 15:24:09.754066+00:00
[2024-12-07T15:24:10.022+0000] {logging_mixin.py:190} INFO - Dag name:medal_count_dag and current dag run status:running
[2024-12-07T15:24:10.022+0000] {taskinstance.py:731} INFO - ::endgroup::
[2024-12-07T15:24:10.023+0000] {sql.py:278} INFO - Executing: 
CREATE TABLE IF NOT EXISTS medal_count (
    id SERIAL PRIMARY KEY,
    medal_type VARCHAR(50),
    count INTEGER,
    created_at TIMESTAMP
);
[2024-12-07T15:24:10.032+0000] {base.py:84} INFO - Retrieving connection 'goit_mysql_db_volodymyrdubrovskyi'
[2024-12-07T15:24:10.038+0000] {base.py:84} INFO - Retrieving connection 'goit_mysql_db_volodymyrdubrovskyi'
[2024-12-07T15:24:10.550+0000] {taskinstance.py:3311} ERROR - Task failed with exception
Traceback (most recent call last):
  File "/home/airflow/.local/lib/python3.12/site-packages/airflow/models/taskinstance.py", line 767, in _execute_task
    result = _execute_callable(context=context, **execute_callable_kwargs)
             ^^^^^^^^^^^^^^^^^^^^^^^^^^^^^^^^^^^^^^^^^^^^^^^^^^^^^^^^^^^^^
  File "/home/airflow/.local/lib/python3.12/site-packages/airflow/models/taskinstance.py", line 733, in _execute_callable
    return ExecutionCallableRunner(
           ^^^^^^^^^^^^^^^^^^^^^^^^
  File "/home/airflow/.local/lib/python3.12/site-packages/airflow/utils/operator_helpers.py", line 252, in run
    return self.func(*args, **kwargs)
           ^^^^^^^^^^^^^^^^^^^^^^^^^^
  File "/home/airflow/.local/lib/python3.12/site-packages/airflow/models/baseoperator.py", line 417, in wrapper
    return func(self, *args, **kwargs)
           ^^^^^^^^^^^^^^^^^^^^^^^^^^^
  File "/home/airflow/.local/lib/python3.12/site-packages/airflow/providers/common/sql/operators/sql.py", line 284, in execute
    output = hook.run(
             ^^^^^^^^^
  File "/home/airflow/.local/lib/python3.12/site-packages/airflow/providers/common/sql/hooks/sql.py", line 485, in run
    with self._create_autocommit_connection(autocommit) as conn:
         ^^^^^^^^^^^^^^^^^^^^^^^^^^^^^^^^^^^^^^^^^^^^^^
  File "/usr/local/lib/python3.12/contextlib.py", line 137, in __enter__
    return next(self.gen)
           ^^^^^^^^^^^^^^
  File "/home/airflow/.local/lib/python3.12/site-packages/airflow/providers/common/sql/hooks/sql.py", line 609, in _create_autocommit_connection
    with closing(self.get_conn()) as conn:
                 ^^^^^^^^^^^^^^^
  File "/home/airflow/.local/lib/python3.12/site-packages/airflow/providers/mysql/hooks/mysql.py", line 200, in get_conn
    return MySQLdb.connect(**conn_config)
           ^^^^^^^^^^^^^^^^^^^^^^^^^^^^^^
  File "/home/airflow/.local/lib/python3.12/site-packages/MySQLdb/__init__.py", line 121, in Connect
    return Connection(*args, **kwargs)
           ^^^^^^^^^^^^^^^^^^^^^^^^^^^
  File "/home/airflow/.local/lib/python3.12/site-packages/MySQLdb/connections.py", line 195, in __init__
    super().__init__(*args, **kwargs2)
MySQLdb.OperationalError: (1045, "Access denied for user 'neo_data_admin'@'188.163.74.46' (using password: NO)")
[2024-12-07T15:24:10.569+0000] {logging_mixin.py:190} INFO - Task instance in failure state
[2024-12-07T15:24:10.571+0000] {logging_mixin.py:190} INFO - Task start:2024-12-07 15:24:09.754066+00:00 end:2024-12-07 15:24:10.569358+00:00 duration:0.815292
[2024-12-07T15:24:10.572+0000] {logging_mixin.py:190} INFO - Task:<Task(MySqlOperator): create_table> dag:<DAG: medal_count_dag> dagrun:<DagRun medal_count_dag @ 2024-12-07 15:24:04.673694+00:00: manual__2024-12-07T15:24:04.673694+00:00, state:running, queued_at: 2024-12-07 15:24:04.691690+00:00. externally triggered: True>
[2024-12-07T15:24:10.572+0000] {logging_mixin.py:190} INFO - Failure caused by (1045, "Access denied for user 'neo_data_admin'@'188.163.74.46' (using password: NO)")
[2024-12-07T15:24:10.573+0000] {taskinstance.py:1225} INFO - Marking task as UP_FOR_RETRY. dag_id=medal_count_dag, task_id=create_table, run_id=manual__2024-12-07T15:24:04.673694+00:00, execution_date=20241207T152404, start_date=20241207T152409, end_date=20241207T152410
[2024-12-07T15:24:10.588+0000] {taskinstance.py:340} INFO - ::group::Post task execution logs
[2024-12-07T15:24:10.589+0000] {standard_task_runner.py:124} ERROR - Failed to execute job 3 for task create_table ((1045, "Access denied for user 'neo_data_admin'@'188.163.74.46' (using password: NO)"); 1459)
Traceback (most recent call last):
  File "/home/airflow/.local/lib/python3.12/site-packages/airflow/task/task_runner/standard_task_runner.py", line 117, in _start_by_fork
    ret = args.func(args, dag=self.dag)
          ^^^^^^^^^^^^^^^^^^^^^^^^^^^^^
  File "/home/airflow/.local/lib/python3.12/site-packages/airflow/cli/cli_config.py", line 49, in command
    return func(*args, **kwargs)
           ^^^^^^^^^^^^^^^^^^^^^
  File "/home/airflow/.local/lib/python3.12/site-packages/airflow/utils/cli.py", line 116, in wrapper
    return f(*args, **kwargs)
           ^^^^^^^^^^^^^^^^^^
  File "/home/airflow/.local/lib/python3.12/site-packages/airflow/cli/commands/task_command.py", line 483, in task_run
    task_return_code = _run_task_by_selected_method(args, _dag, ti)
                       ^^^^^^^^^^^^^^^^^^^^^^^^^^^^^^^^^^^^^^^^^^^^
  File "/home/airflow/.local/lib/python3.12/site-packages/airflow/cli/commands/task_command.py", line 256, in _run_task_by_selected_method
    return _run_raw_task(args, ti)
           ^^^^^^^^^^^^^^^^^^^^^^^
  File "/home/airflow/.local/lib/python3.12/site-packages/airflow/cli/commands/task_command.py", line 341, in _run_raw_task
    return ti._run_raw_task(
           ^^^^^^^^^^^^^^^^^
  File "/home/airflow/.local/lib/python3.12/site-packages/airflow/utils/session.py", line 97, in wrapper
    return func(*args, session=session, **kwargs)
           ^^^^^^^^^^^^^^^^^^^^^^^^^^^^^^^^^^^^^^
  File "/home/airflow/.local/lib/python3.12/site-packages/airflow/models/taskinstance.py", line 3005, in _run_raw_task
    return _run_raw_task(
           ^^^^^^^^^^^^^^
  File "/home/airflow/.local/lib/python3.12/site-packages/airflow/models/taskinstance.py", line 273, in _run_raw_task
    TaskInstance._execute_task_with_callbacks(
  File "/home/airflow/.local/lib/python3.12/site-packages/airflow/models/taskinstance.py", line 3159, in _execute_task_with_callbacks
    result = self._execute_task(context, task_orig)
             ^^^^^^^^^^^^^^^^^^^^^^^^^^^^^^^^^^^^^^
  File "/home/airflow/.local/lib/python3.12/site-packages/airflow/models/taskinstance.py", line 3183, in _execute_task
    return _execute_task(self, context, task_orig)
           ^^^^^^^^^^^^^^^^^^^^^^^^^^^^^^^^^^^^^^^
  File "/home/airflow/.local/lib/python3.12/site-packages/airflow/models/taskinstance.py", line 767, in _execute_task
    result = _execute_callable(context=context, **execute_callable_kwargs)
             ^^^^^^^^^^^^^^^^^^^^^^^^^^^^^^^^^^^^^^^^^^^^^^^^^^^^^^^^^^^^^
  File "/home/airflow/.local/lib/python3.12/site-packages/airflow/models/taskinstance.py", line 733, in _execute_callable
    return ExecutionCallableRunner(
           ^^^^^^^^^^^^^^^^^^^^^^^^
  File "/home/airflow/.local/lib/python3.12/site-packages/airflow/utils/operator_helpers.py", line 252, in run
    return self.func(*args, **kwargs)
           ^^^^^^^^^^^^^^^^^^^^^^^^^^
  File "/home/airflow/.local/lib/python3.12/site-packages/airflow/models/baseoperator.py", line 417, in wrapper
    return func(self, *args, **kwargs)
           ^^^^^^^^^^^^^^^^^^^^^^^^^^^
  File "/home/airflow/.local/lib/python3.12/site-packages/airflow/providers/common/sql/operators/sql.py", line 284, in execute
    output = hook.run(
             ^^^^^^^^^
  File "/home/airflow/.local/lib/python3.12/site-packages/airflow/providers/common/sql/hooks/sql.py", line 485, in run
    with self._create_autocommit_connection(autocommit) as conn:
         ^^^^^^^^^^^^^^^^^^^^^^^^^^^^^^^^^^^^^^^^^^^^^^
  File "/usr/local/lib/python3.12/contextlib.py", line 137, in __enter__
    return next(self.gen)
           ^^^^^^^^^^^^^^
  File "/home/airflow/.local/lib/python3.12/site-packages/airflow/providers/common/sql/hooks/sql.py", line 609, in _create_autocommit_connection
    with closing(self.get_conn()) as conn:
                 ^^^^^^^^^^^^^^^
  File "/home/airflow/.local/lib/python3.12/site-packages/airflow/providers/mysql/hooks/mysql.py", line 200, in get_conn
    return MySQLdb.connect(**conn_config)
           ^^^^^^^^^^^^^^^^^^^^^^^^^^^^^^
  File "/home/airflow/.local/lib/python3.12/site-packages/MySQLdb/__init__.py", line 121, in Connect
    return Connection(*args, **kwargs)
           ^^^^^^^^^^^^^^^^^^^^^^^^^^^
  File "/home/airflow/.local/lib/python3.12/site-packages/MySQLdb/connections.py", line 195, in __init__
    super().__init__(*args, **kwargs2)
MySQLdb.OperationalError: (1045, "Access denied for user 'neo_data_admin'@'188.163.74.46' (using password: NO)")
[2024-12-07T15:24:10.613+0000] {local_task_job_runner.py:266} INFO - Task exited with return code 1
[2024-12-07T15:24:10.640+0000] {taskinstance.py:3895} INFO - 0 downstream tasks scheduled from follow-on schedule check
[2024-12-07T15:24:10.643+0000] {local_task_job_runner.py:245} INFO - ::endgroup::
